2025-07-30 00:16:16,325 - INFO - Command used | Guild: BhaluGang (1208701086458847282) | User: itsvirus07#0 (482482011571748864) | Command: join
2025-07-30 00:16:37,457 - ERROR - [command_error] Command raised an exception: TimeoutError:  | Additional info: {'guild_id': 1208701086458847282}
NoneType: None
2025-07-30 00:17:18,383 - ERROR - [command_error] Command raised an exception: TimeoutError:  | Additional info: {'guild_id': 1208701086458847282}
NoneType: None
2025-07-30 00:18:32,476 - INFO - Starting Music Bot...
2025-07-30 00:18:33,478 - INFO - Starting bot setup...
2025-07-30 00:18:33,486 - INFO - All command modules loaded successfully
2025-07-30 00:18:33,486 - INFO - Bot setup completed successfully
2025-07-30 00:18:36,538 - INFO - Bot is ready! Logged in as Neha (1397919621473894470)
2025-07-30 00:18:36,538 - INFO - Connected to 4 guilds
2025-07-30 00:18:36,538 - INFO - Serving 295 users
2025-07-30 00:18:49,151 - INFO - Starting Music Bot...
2025-07-30 00:18:50,147 - INFO - Starting bot setup...
2025-07-30 00:18:50,159 - INFO - All command modules loaded successfully
2025-07-30 00:18:50,159 - INFO - Bot setup completed successfully
2025-07-30 00:18:53,091 - INFO - Bot is ready! Logged in as Neha (1397919621473894470)
2025-07-30 00:18:53,091 - INFO - Connected to 4 guilds
2025-07-30 00:18:53,091 - INFO - Serving 295 users
2025-07-30 00:19:03,132 - INFO - Command used | Guild: BhaluGang (1208701086458847282) | User: itsvirus07#0 (482482011571748864) | Command: play Args: Pankaj Udhas - Chandi Jaisa Rang
2025-07-30 00:19:03,140 - INFO - Command used | Guild: BhaluGang (1208701086458847282) | User: itsvirus07#0 (482482011571748864) | Command: play Args: Pankaj Udhas - Chandi Jaisa Rang
2025-07-30 00:19:03,145 - INFO - Command used | Guild: BhaluGang (1208701086458847282) | User: itsvirus07#0 (482482011571748864) | Command: play Args: Pankaj Udhas - Chandi Jaisa Rang
2025-07-30 00:20:03,146 - ERROR - [play_command_error] Command raised an exception: TimeoutError:  | Additional info: {'guild_id': 1208701086458847282, 'user_id': 482482011571748864}
Traceback (most recent call last):
  File "C:\Users\amitk\AppData\Local\Programs\Python\Python312\Lib\asyncio\tasks.py", line 510, in wait_for
    return await fut
           ^^^^^^^^^
  File "C:\Users\amitk\AppData\Local\Programs\Python\Python312\Lib\site-packages\discord\voice_state.py", line 407, in _inner_connect
    await self._wait_for_state(ConnectionFlowState.got_both_voice_updates)
  File "C:\Users\amitk\AppData\Local\Programs\Python\Python312\Lib\site-packages\discord\voice_state.py", line 559, in _wait_for_state
    await sane_wait_for([self._state_event.wait()], timeout=timeout)
  File "C:\Users\amitk\AppData\Local\Programs\Python\Python312\Lib\site-packages\discord\utils.py", line 735, in sane_wait_for
    done, pending = await asyncio.wait(ensured, timeout=timeout, return_when=asyncio.ALL_COMPLETED)
                    ^^^^^^^^^^^^^^^^^^^^^^^^^^^^^^^^^^^^^^^^^^^^^^^^^^^^^^^^^^^^^^^^^^^^^^^^^^^^^^^
  File "C:\Users\amitk\AppData\Local\Programs\Python\Python312\Lib\asyncio\tasks.py", line 454, in wait
    return await _wait(fs, timeout, return_when, loop)
           ^^^^^^^^^^^^^^^^^^^^^^^^^^^^^^^^^^^^^^^^^^^
  File "C:\Users\amitk\AppData\Local\Programs\Python\Python312\Lib\asyncio\tasks.py", line 540, in _wait
    await waiter
asyncio.exceptions.CancelledError

The above exception was the direct cause of the following exception:

Traceback (most recent call last):
  File "C:\Users\amitk\AppData\Local\Programs\Python\Python312\Lib\site-packages\discord\ext\commands\core.py", line 235, in wrapped
    ret = await coro(*args, **kwargs)
          ^^^^^^^^^^^^^^^^^^^^^^^^^^^
  File "C:\Users\amitk\Documents\Music Bot\commands\music.py", line 64, in play
    await ctx.author.voice.channel.connect()
  File "C:\Users\amitk\AppData\Local\Programs\Python\Python312\Lib\site-packages\discord\abc.py", line 1992, in connect
    await voice.connect(timeout=timeout, reconnect=reconnect, self_deaf=self_deaf, self_mute=self_mute)
  File "C:\Users\amitk\AppData\Local\Programs\Python\Python312\Lib\site-packages\discord\voice_client.py", line 306, in connect
    await self._connection.connect(
  File "C:\Users\amitk\AppData\Local\Programs\Python\Python312\Lib\site-packages\discord\voice_state.py", line 380, in connect
    await self._connector
  File "C:\Users\amitk\AppData\Local\Programs\Python\Python312\Lib\site-packages\discord\voice_state.py", line 384, in _wrap_connect
    await self._connect(*args)
  File "C:\Users\amitk\AppData\Local\Programs\Python\Python312\Lib\site-packages\discord\voice_state.py", line 429, in _connect
    await asyncio.wait_for(
  File "C:\Users\amitk\AppData\Local\Programs\Python\Python312\Lib\asyncio\tasks.py", line 509, in wait_for
    async with timeouts.timeout(timeout):
  File "C:\Users\amitk\AppData\Local\Programs\Python\Python312\Lib\asyncio\timeouts.py", line 111, in __aexit__
    raise TimeoutError from exc_val
TimeoutError

The above exception was the direct cause of the following exception:

Traceback (most recent call last):
  File "C:\Users\amitk\AppData\Local\Programs\Python\Python312\Lib\site-packages\discord\ext\commands\bot.py", line 1366, in invoke
    await ctx.command.invoke(ctx)
  File "C:\Users\amitk\AppData\Local\Programs\Python\Python312\Lib\site-packages\discord\ext\commands\core.py", line 1029, in invoke
    await injected(*ctx.args, **ctx.kwargs)  # type: ignore
    ^^^^^^^^^^^^^^^^^^^^^^^^^^^^^^^^^^^^^^^
  File "C:\Users\amitk\AppData\Local\Programs\Python\Python312\Lib\site-packages\discord\ext\commands\core.py", line 244, in wrapped
    raise CommandInvokeError(exc) from exc
discord.ext.commands.errors.CommandInvokeError: Command raised an exception: TimeoutError: 
2025-07-30 00:20:03,162 - ERROR - [play_command_error] Command raised an exception: TimeoutError:  | Additional info: {'guild_id': 1208701086458847282, 'user_id': 482482011571748864}
Traceback (most recent call last):
  File "C:\Users\amitk\AppData\Local\Programs\Python\Python312\Lib\site-packages\discord\voice_state.py", line 413, in _inner_connect
    await self._handshake_websocket()
  File "C:\Users\amitk\AppData\Local\Programs\Python\Python312\Lib\site-packages\discord\voice_state.py", line 583, in _handshake_websocket
    await self.ws.poll_event()
  File "C:\Users\amitk\AppData\Local\Programs\Python\Python312\Lib\site-packages\discord\gateway.py", line 1039, in poll_event
    raise ConnectionClosed(self.ws, shard_id=None, code=self._close_code)
discord.errors.ConnectionClosed: Shard ID None WebSocket closed with 4006

During handling of the above exception, another exception occurred:

Traceback (most recent call last):
  File "C:\Users\amitk\AppData\Local\Programs\Python\Python312\Lib\asyncio\tasks.py", line 510, in wait_for
    return await fut
           ^^^^^^^^^
  File "C:\Users\amitk\AppData\Local\Programs\Python\Python312\Lib\site-packages\discord\voice_state.py", line 420, in _inner_connect
    await asyncio.sleep(wait)
  File "C:\Users\amitk\AppData\Local\Programs\Python\Python312\Lib\asyncio\tasks.py", line 655, in sleep
    return await future
           ^^^^^^^^^^^^
asyncio.exceptions.CancelledError

The above exception was the direct cause of the following exception:

Traceback (most recent call last):
  File "C:\Users\amitk\AppData\Local\Programs\Python\Python312\Lib\site-packages\discord\ext\commands\core.py", line 235, in wrapped
    ret = await coro(*args, **kwargs)
          ^^^^^^^^^^^^^^^^^^^^^^^^^^^
  File "C:\Users\amitk\Documents\Music Bot\commands\music.py", line 64, in play
    await ctx.author.voice.channel.connect()
  File "C:\Users\amitk\AppData\Local\Programs\Python\Python312\Lib\site-packages\discord\abc.py", line 1992, in connect
    await voice.connect(timeout=timeout, reconnect=reconnect, self_deaf=self_deaf, self_mute=self_mute)
  File "C:\Users\amitk\AppData\Local\Programs\Python\Python312\Lib\site-packages\discord\voice_client.py", line 306, in connect
    await self._connection.connect(
  File "C:\Users\amitk\AppData\Local\Programs\Python\Python312\Lib\site-packages\discord\voice_state.py", line 380, in connect
    await self._connector
  File "C:\Users\amitk\AppData\Local\Programs\Python\Python312\Lib\site-packages\discord\voice_state.py", line 384, in _wrap_connect
    await self._connect(*args)
  File "C:\Users\amitk\AppData\Local\Programs\Python\Python312\Lib\site-packages\discord\voice_state.py", line 429, in _connect
    await asyncio.wait_for(
  File "C:\Users\amitk\AppData\Local\Programs\Python\Python312\Lib\asyncio\tasks.py", line 509, in wait_for
    async with timeouts.timeout(timeout):
  File "C:\Users\amitk\AppData\Local\Programs\Python\Python312\Lib\asyncio\timeouts.py", line 111, in __aexit__
    raise TimeoutError from exc_val
TimeoutError

The above exception was the direct cause of the following exception:

Traceback (most recent call last):
  File "C:\Users\amitk\AppData\Local\Programs\Python\Python312\Lib\site-packages\discord\ext\commands\bot.py", line 1366, in invoke
    await ctx.command.invoke(ctx)
  File "C:\Users\amitk\AppData\Local\Programs\Python\Python312\Lib\site-packages\discord\ext\commands\core.py", line 1029, in invoke
    await injected(*ctx.args, **ctx.kwargs)  # type: ignore
    ^^^^^^^^^^^^^^^^^^^^^^^^^^^^^^^^^^^^^^^
  File "C:\Users\amitk\AppData\Local\Programs\Python\Python312\Lib\site-packages\discord\ext\commands\core.py", line 244, in wrapped
    raise CommandInvokeError(exc) from exc
discord.ext.commands.errors.CommandInvokeError: Command raised an exception: TimeoutError: 
2025-07-30 00:20:03,162 - ERROR - [play_command_error] Command raised an exception: TimeoutError:  | Additional info: {'guild_id': 1208701086458847282, 'user_id': 482482011571748864}
Traceback (most recent call last):
  File "C:\Users\amitk\AppData\Local\Programs\Python\Python312\Lib\asyncio\tasks.py", line 510, in wait_for
    return await fut
           ^^^^^^^^^
  File "C:\Users\amitk\AppData\Local\Programs\Python\Python312\Lib\site-packages\discord\voice_state.py", line 407, in _inner_connect
    await self._wait_for_state(ConnectionFlowState.got_both_voice_updates)
  File "C:\Users\amitk\AppData\Local\Programs\Python\Python312\Lib\site-packages\discord\voice_state.py", line 559, in _wait_for_state
    await sane_wait_for([self._state_event.wait()], timeout=timeout)
  File "C:\Users\amitk\AppData\Local\Programs\Python\Python312\Lib\site-packages\discord\utils.py", line 735, in sane_wait_for
    done, pending = await asyncio.wait(ensured, timeout=timeout, return_when=asyncio.ALL_COMPLETED)
                    ^^^^^^^^^^^^^^^^^^^^^^^^^^^^^^^^^^^^^^^^^^^^^^^^^^^^^^^^^^^^^^^^^^^^^^^^^^^^^^^
  File "C:\Users\amitk\AppData\Local\Programs\Python\Python312\Lib\asyncio\tasks.py", line 454, in wait
    return await _wait(fs, timeout, return_when, loop)
           ^^^^^^^^^^^^^^^^^^^^^^^^^^^^^^^^^^^^^^^^^^^
  File "C:\Users\amitk\AppData\Local\Programs\Python\Python312\Lib\asyncio\tasks.py", line 540, in _wait
    await waiter
asyncio.exceptions.CancelledError

The above exception was the direct cause of the following exception:

Traceback (most recent call last):
  File "C:\Users\amitk\AppData\Local\Programs\Python\Python312\Lib\site-packages\discord\ext\commands\core.py", line 235, in wrapped
    ret = await coro(*args, **kwargs)
          ^^^^^^^^^^^^^^^^^^^^^^^^^^^
  File "C:\Users\amitk\Documents\Music Bot\commands\music.py", line 64, in play
    await ctx.author.voice.channel.connect()
  File "C:\Users\amitk\AppData\Local\Programs\Python\Python312\Lib\site-packages\discord\abc.py", line 1992, in connect
    await voice.connect(timeout=timeout, reconnect=reconnect, self_deaf=self_deaf, self_mute=self_mute)
  File "C:\Users\amitk\AppData\Local\Programs\Python\Python312\Lib\site-packages\discord\voice_client.py", line 306, in connect
    await self._connection.connect(
  File "C:\Users\amitk\AppData\Local\Programs\Python\Python312\Lib\site-packages\discord\voice_state.py", line 380, in connect
    await self._connector
  File "C:\Users\amitk\AppData\Local\Programs\Python\Python312\Lib\site-packages\discord\voice_state.py", line 384, in _wrap_connect
    await self._connect(*args)
  File "C:\Users\amitk\AppData\Local\Programs\Python\Python312\Lib\site-packages\discord\voice_state.py", line 429, in _connect
    await asyncio.wait_for(
  File "C:\Users\amitk\AppData\Local\Programs\Python\Python312\Lib\asyncio\tasks.py", line 509, in wait_for
    async with timeouts.timeout(timeout):
  File "C:\Users\amitk\AppData\Local\Programs\Python\Python312\Lib\asyncio\timeouts.py", line 111, in __aexit__
    raise TimeoutError from exc_val
TimeoutError

The above exception was the direct cause of the following exception:

Traceback (most recent call last):
  File "C:\Users\amitk\AppData\Local\Programs\Python\Python312\Lib\site-packages\discord\ext\commands\bot.py", line 1366, in invoke
    await ctx.command.invoke(ctx)
  File "C:\Users\amitk\AppData\Local\Programs\Python\Python312\Lib\site-packages\discord\ext\commands\core.py", line 1029, in invoke
    await injected(*ctx.args, **ctx.kwargs)  # type: ignore
    ^^^^^^^^^^^^^^^^^^^^^^^^^^^^^^^^^^^^^^^
  File "C:\Users\amitk\AppData\Local\Programs\Python\Python312\Lib\site-packages\discord\ext\commands\core.py", line 244, in wrapped
    raise CommandInvokeError(exc) from exc
discord.ext.commands.errors.CommandInvokeError: Command raised an exception: TimeoutError: 
2025-07-30 00:20:04,356 - ERROR - [command_error] Command raised an exception: TimeoutError:  | Additional info: {'guild_id': 1208701086458847282}
NoneType: None
2025-07-30 00:20:04,461 - ERROR - [command_error] Command raised an exception: TimeoutError:  | Additional info: {'guild_id': 1208701086458847282}
NoneType: None
2025-07-30 00:20:04,577 - INFO - Starting enhanced dashboard on http://127.0.0.1:5000
2025-07-30 00:20:04,947 - INFO - Starting enhanced dashboard on http://127.0.0.1:5000
2025-07-30 00:20:09,715 - ERROR - [command_error] Command raised an exception: TimeoutError:  | Additional info: {'guild_id': 1208701086458847282}
NoneType: None
2025-07-30 00:20:17,707 - ERROR - [dashboard_index] expected token 'end of statement block', got '['
Traceback (most recent call last):
  File "C:\Users\amitk\Documents\Music Bot\dashboard.py", line 169, in index
    return render_template('dashboard_enhanced.html', stats=stats)
           ^^^^^^^^^^^^^^^^^^^^^^^^^^^^^^^^^^^^^^^^^^^^^^^^^^^^^^^
  File "C:\Users\amitk\AppData\Local\Programs\Python\Python312\Lib\site-packages\flask\templating.py", line 150, in render_template
    template = app.jinja_env.get_or_select_template(template_name_or_list)
               ^^^^^^^^^^^^^^^^^^^^^^^^^^^^^^^^^^^^^^^^^^^^^^^^^^^^^^^^^^^
  File "C:\Users\amitk\AppData\Local\Programs\Python\Python312\Lib\site-packages\jinja2\environment.py", line 1087, in get_or_select_template
    return self.get_template(template_name_or_list, parent, globals)
           ^^^^^^^^^^^^^^^^^^^^^^^^^^^^^^^^^^^^^^^^^^^^^^^^^^^^^^^^^
  File "C:\Users\amitk\AppData\Local\Programs\Python\Python312\Lib\site-packages\jinja2\environment.py", line 1016, in get_template
    return self._load_template(name, globals)
           ^^^^^^^^^^^^^^^^^^^^^^^^^^^^^^^^^^
  File "C:\Users\amitk\AppData\Local\Programs\Python\Python312\Lib\site-packages\jinja2\environment.py", line 975, in _load_template
    template = self.loader.load(self, name, self.make_globals(globals))
               ^^^^^^^^^^^^^^^^^^^^^^^^^^^^^^^^^^^^^^^^^^^^^^^^^^^^^^^^
  File "C:\Users\amitk\AppData\Local\Programs\Python\Python312\Lib\site-packages\jinja2\loaders.py", line 138, in load
    code = environment.compile(source, name, filename)
           ^^^^^^^^^^^^^^^^^^^^^^^^^^^^^^^^^^^^^^^^^^^
  File "C:\Users\amitk\AppData\Local\Programs\Python\Python312\Lib\site-packages\jinja2\environment.py", line 771, in compile
    self.handle_exception(source=source_hint)
  File "C:\Users\amitk\AppData\Local\Programs\Python\Python312\Lib\site-packages\jinja2\environment.py", line 942, in handle_exception
    raise rewrite_traceback_stack(source=source)
  File "C:\Users\amitk\Documents\Music Bot\templates\dashboard_enhanced.html", line 193, in template
    {% for song, count in stats.most_played.items() | list[:10] %}
    ^^^^^^^^^^^^^^^^^^^^^^^^^
jinja2.exceptions.TemplateSyntaxError: expected token 'end of statement block', got '['
2025-07-30 00:20:27,677 - INFO - Bot stopped by user
2025-07-30 00:21:18,032 - INFO - Starting Music Bot...
2025-07-30 00:21:19,146 - INFO - Starting bot setup...
2025-07-30 00:21:19,150 - INFO - All command modules loaded successfully
2025-07-30 00:21:19,150 - INFO - Bot setup completed successfully
2025-07-30 00:21:22,228 - INFO - Bot is ready! Logged in as Neha (1397919621473894470)
2025-07-30 00:21:22,228 - INFO - Connected to 4 guilds
2025-07-30 00:21:22,243 - INFO - Serving 295 users
2025-07-30 00:21:24,934 - INFO - Command used | Guild: funny server (1053223116085673985) | User: itsvirus07#0 (482482011571748864) | Command: play Args: Pankaj Udhas - Chandi Jaisa Rang
2025-07-30 00:21:24,938 - INFO - Command used | Guild: funny server (1053223116085673985) | User: itsvirus07#0 (482482011571748864) | Command: play Args: Pankaj Udhas - Chandi Jaisa Rang
2025-07-30 00:21:31,437 - INFO - Command used | Guild: funny server (1053223116085673985) | User: itsvirus07#0 (482482011571748864) | Command: play Args: Pankaj Udhas - Chandi Jaisa Rang
2025-07-30 00:21:31,441 - INFO - Command used | Guild: funny server (1053223116085673985) | User: itsvirus07#0 (482482011571748864) | Command: play Args: Pankaj Udhas - Chandi Jaisa Rang
2025-07-30 00:21:31,445 - INFO - Command used | Guild: funny server (1053223116085673985) | User: itsvirus07#0 (482482011571748864) | Command: play Args: Pankaj Udhas - Chandi Jaisa Rang
2025-07-30 00:21:41,237 - INFO - Audio event: song_resolved | Guild: 0 | Song: Pankaj Udhas - Chandi Jaisa Rang (attempt 1)
2025-07-30 00:21:41,254 - INFO - Recorded song play: Pankaj Udhas - Chandi Jaisa Rang in guild 1053223116085673985 (funny server)
2025-07-30 00:21:42,369 - INFO - Audio event: song_started | Guild: 1053223116085673985 | Song: Pankaj Udhas - Chandi Jaisa Rang
2025-07-30 00:21:45,112 - INFO - Audio event: songs_added | Guild: 1053223116085673985 | Song: 1 songs
2025-07-30 00:22:28,098 - INFO - Command used | Guild: funny server (1053223116085673985) | User: itsvirus07#0 (482482011571748864) | Command: leave
2025-07-30 00:22:28,102 - INFO - Command used | Guild: funny server (1053223116085673985) | User: itsvirus07#0 (482482011571748864) | Command: leave
2025-07-30 00:22:28,117 - INFO - Command used | Guild: funny server (1053223116085673985) | User: itsvirus07#0 (482482011571748864) | Command: leave
2025-07-30 00:22:29,547 - WARNING - No current song found: queue is empty | Context: {'guild_id': 1053223116085673985}
2025-07-30 00:22:29,548 - INFO - Audio event: queue_finished | Guild: 1053223116085673985
2025-07-30 00:22:30,973 - INFO - Audio event: left_voice_channel | Guild: 1053223116085673985
2025-07-30 00:22:31,451 - ERROR - [play_command_error] Command raised an exception: TimeoutError:  | Additional info: {'guild_id': 1053223116085673985, 'user_id': 482482011571748864}
Traceback (most recent call last):
  File "C:\Users\amitk\AppData\Local\Programs\Python\Python312\Lib\asyncio\tasks.py", line 510, in wait_for
    return await fut
           ^^^^^^^^^
  File "C:\Users\amitk\AppData\Local\Programs\Python\Python312\Lib\site-packages\discord\voice_state.py", line 407, in _inner_connect
    await self._wait_for_state(ConnectionFlowState.got_both_voice_updates)
  File "C:\Users\amitk\AppData\Local\Programs\Python\Python312\Lib\site-packages\discord\voice_state.py", line 559, in _wait_for_state
    await sane_wait_for([self._state_event.wait()], timeout=timeout)
  File "C:\Users\amitk\AppData\Local\Programs\Python\Python312\Lib\site-packages\discord\utils.py", line 735, in sane_wait_for
    done, pending = await asyncio.wait(ensured, timeout=timeout, return_when=asyncio.ALL_COMPLETED)
                    ^^^^^^^^^^^^^^^^^^^^^^^^^^^^^^^^^^^^^^^^^^^^^^^^^^^^^^^^^^^^^^^^^^^^^^^^^^^^^^^
  File "C:\Users\amitk\AppData\Local\Programs\Python\Python312\Lib\asyncio\tasks.py", line 454, in wait
    return await _wait(fs, timeout, return_when, loop)
           ^^^^^^^^^^^^^^^^^^^^^^^^^^^^^^^^^^^^^^^^^^^
  File "C:\Users\amitk\AppData\Local\Programs\Python\Python312\Lib\asyncio\tasks.py", line 540, in _wait
    await waiter
asyncio.exceptions.CancelledError

The above exception was the direct cause of the following exception:

Traceback (most recent call last):
  File "C:\Users\amitk\AppData\Local\Programs\Python\Python312\Lib\site-packages\discord\ext\commands\core.py", line 235, in wrapped
    ret = await coro(*args, **kwargs)
          ^^^^^^^^^^^^^^^^^^^^^^^^^^^
  File "C:\Users\amitk\Documents\Music Bot\commands\music.py", line 64, in play
    await ctx.author.voice.channel.connect()
  File "C:\Users\amitk\AppData\Local\Programs\Python\Python312\Lib\site-packages\discord\abc.py", line 1992, in connect
    await voice.connect(timeout=timeout, reconnect=reconnect, self_deaf=self_deaf, self_mute=self_mute)
  File "C:\Users\amitk\AppData\Local\Programs\Python\Python312\Lib\site-packages\discord\voice_client.py", line 306, in connect
    await self._connection.connect(
  File "C:\Users\amitk\AppData\Local\Programs\Python\Python312\Lib\site-packages\discord\voice_state.py", line 380, in connect
    await self._connector
  File "C:\Users\amitk\AppData\Local\Programs\Python\Python312\Lib\site-packages\discord\voice_state.py", line 384, in _wrap_connect
    await self._connect(*args)
  File "C:\Users\amitk\AppData\Local\Programs\Python\Python312\Lib\site-packages\discord\voice_state.py", line 429, in _connect
    await asyncio.wait_for(
  File "C:\Users\amitk\AppData\Local\Programs\Python\Python312\Lib\asyncio\tasks.py", line 509, in wait_for
    async with timeouts.timeout(timeout):
  File "C:\Users\amitk\AppData\Local\Programs\Python\Python312\Lib\asyncio\timeouts.py", line 111, in __aexit__
    raise TimeoutError from exc_val
TimeoutError

The above exception was the direct cause of the following exception:

Traceback (most recent call last):
  File "C:\Users\amitk\AppData\Local\Programs\Python\Python312\Lib\site-packages\discord\ext\commands\bot.py", line 1366, in invoke
    await ctx.command.invoke(ctx)
  File "C:\Users\amitk\AppData\Local\Programs\Python\Python312\Lib\site-packages\discord\ext\commands\core.py", line 1029, in invoke
    await injected(*ctx.args, **ctx.kwargs)  # type: ignore
    ^^^^^^^^^^^^^^^^^^^^^^^^^^^^^^^^^^^^^^^
  File "C:\Users\amitk\AppData\Local\Programs\Python\Python312\Lib\site-packages\discord\ext\commands\core.py", line 244, in wrapped
    raise CommandInvokeError(exc) from exc
discord.ext.commands.errors.CommandInvokeError: Command raised an exception: TimeoutError: 
2025-07-30 00:22:31,466 - ERROR - [play_command_error] Command raised an exception: TimeoutError:  | Additional info: {'guild_id': 1053223116085673985, 'user_id': 482482011571748864}
Traceback (most recent call last):
  File "C:\Users\amitk\AppData\Local\Programs\Python\Python312\Lib\asyncio\tasks.py", line 510, in wait_for
    return await fut
           ^^^^^^^^^
  File "C:\Users\amitk\AppData\Local\Programs\Python\Python312\Lib\site-packages\discord\voice_state.py", line 407, in _inner_connect
    await self._wait_for_state(ConnectionFlowState.got_both_voice_updates)
  File "C:\Users\amitk\AppData\Local\Programs\Python\Python312\Lib\site-packages\discord\voice_state.py", line 559, in _wait_for_state
    await sane_wait_for([self._state_event.wait()], timeout=timeout)
  File "C:\Users\amitk\AppData\Local\Programs\Python\Python312\Lib\site-packages\discord\utils.py", line 735, in sane_wait_for
    done, pending = await asyncio.wait(ensured, timeout=timeout, return_when=asyncio.ALL_COMPLETED)
                    ^^^^^^^^^^^^^^^^^^^^^^^^^^^^^^^^^^^^^^^^^^^^^^^^^^^^^^^^^^^^^^^^^^^^^^^^^^^^^^^
  File "C:\Users\amitk\AppData\Local\Programs\Python\Python312\Lib\asyncio\tasks.py", line 454, in wait
    return await _wait(fs, timeout, return_when, loop)
           ^^^^^^^^^^^^^^^^^^^^^^^^^^^^^^^^^^^^^^^^^^^
  File "C:\Users\amitk\AppData\Local\Programs\Python\Python312\Lib\asyncio\tasks.py", line 540, in _wait
    await waiter
asyncio.exceptions.CancelledError

The above exception was the direct cause of the following exception:

Traceback (most recent call last):
  File "C:\Users\amitk\AppData\Local\Programs\Python\Python312\Lib\site-packages\discord\ext\commands\core.py", line 235, in wrapped
    ret = await coro(*args, **kwargs)
          ^^^^^^^^^^^^^^^^^^^^^^^^^^^
  File "C:\Users\amitk\Documents\Music Bot\commands\music.py", line 64, in play
    await ctx.author.voice.channel.connect()
  File "C:\Users\amitk\AppData\Local\Programs\Python\Python312\Lib\site-packages\discord\abc.py", line 1992, in connect
    await voice.connect(timeout=timeout, reconnect=reconnect, self_deaf=self_deaf, self_mute=self_mute)
  File "C:\Users\amitk\AppData\Local\Programs\Python\Python312\Lib\site-packages\discord\voice_client.py", line 306, in connect
    await self._connection.connect(
  File "C:\Users\amitk\AppData\Local\Programs\Python\Python312\Lib\site-packages\discord\voice_state.py", line 380, in connect
    await self._connector
  File "C:\Users\amitk\AppData\Local\Programs\Python\Python312\Lib\site-packages\discord\voice_state.py", line 384, in _wrap_connect
    await self._connect(*args)
  File "C:\Users\amitk\AppData\Local\Programs\Python\Python312\Lib\site-packages\discord\voice_state.py", line 429, in _connect
    await asyncio.wait_for(
  File "C:\Users\amitk\AppData\Local\Programs\Python\Python312\Lib\asyncio\tasks.py", line 509, in wait_for
    async with timeouts.timeout(timeout):
  File "C:\Users\amitk\AppData\Local\Programs\Python\Python312\Lib\asyncio\timeouts.py", line 111, in __aexit__
    raise TimeoutError from exc_val
TimeoutError

The above exception was the direct cause of the following exception:

Traceback (most recent call last):
  File "C:\Users\amitk\AppData\Local\Programs\Python\Python312\Lib\site-packages\discord\ext\commands\bot.py", line 1366, in invoke
    await ctx.command.invoke(ctx)
  File "C:\Users\amitk\AppData\Local\Programs\Python\Python312\Lib\site-packages\discord\ext\commands\core.py", line 1029, in invoke
    await injected(*ctx.args, **ctx.kwargs)  # type: ignore
    ^^^^^^^^^^^^^^^^^^^^^^^^^^^^^^^^^^^^^^^
  File "C:\Users\amitk\AppData\Local\Programs\Python\Python312\Lib\site-packages\discord\ext\commands\core.py", line 244, in wrapped
    raise CommandInvokeError(exc) from exc
discord.ext.commands.errors.CommandInvokeError: Command raised an exception: TimeoutError: 
2025-07-30 00:22:32,379 - ERROR - [command_error] Command raised an exception: TimeoutError:  | Additional info: {'guild_id': 1053223116085673985}
NoneType: None
2025-07-30 00:22:36,628 - ERROR - [command_error] Command raised an exception: TimeoutError:  | Additional info: {'guild_id': 1053223116085673985}
NoneType: None
2025-07-30 00:23:19,646 - INFO - Dashboard background updates stopped
2025-07-30 00:23:20,038 - INFO - Starting enhanced dashboard on http://127.0.0.1:5000
2025-07-30 00:23:30,729 - INFO - Dashboard background updates stopped
2025-07-30 00:23:31,101 - INFO - Starting enhanced dashboard on http://127.0.0.1:5000
2025-07-30 00:24:38,595 - INFO - Command used | Guild: BhaluGang (1208701086458847282) | User: itsvirus07#0 (482482011571748864) | Command: play Args: Hoshwalon Ko Khabar Kya
2025-07-30 00:24:38,597 - INFO - Command used | Guild: BhaluGang (1208701086458847282) | User: itsvirus07#0 (482482011571748864) | Command: play Args: Hoshwalon Ko Khabar Kya
2025-07-30 00:24:38,597 - INFO - Command used | Guild: BhaluGang (1208701086458847282) | User: itsvirus07#0 (482482011571748864) | Command: play Args: Hoshwalon Ko Khabar Kya
2025-07-30 00:24:54,066 - INFO - Bot stopped by user
2025-07-30 00:25:38,622 - ERROR - [play_command_error] Command raised an exception: TimeoutError:  | Additional info: {'guild_id': 1208701086458847282, 'user_id': 482482011571748864}
Traceback (most recent call last):
  File "C:\Users\amitk\AppData\Local\Programs\Python\Python312\Lib\asyncio\tasks.py", line 510, in wait_for
    return await fut
           ^^^^^^^^^
  File "C:\Users\amitk\AppData\Local\Programs\Python\Python312\Lib\site-packages\discord\voice_state.py", line 407, in _inner_connect
    await self._wait_for_state(ConnectionFlowState.got_both_voice_updates)
  File "C:\Users\amitk\AppData\Local\Programs\Python\Python312\Lib\site-packages\discord\voice_state.py", line 559, in _wait_for_state
    await sane_wait_for([self._state_event.wait()], timeout=timeout)
  File "C:\Users\amitk\AppData\Local\Programs\Python\Python312\Lib\site-packages\discord\utils.py", line 735, in sane_wait_for
    done, pending = await asyncio.wait(ensured, timeout=timeout, return_when=asyncio.ALL_COMPLETED)
                    ^^^^^^^^^^^^^^^^^^^^^^^^^^^^^^^^^^^^^^^^^^^^^^^^^^^^^^^^^^^^^^^^^^^^^^^^^^^^^^^
  File "C:\Users\amitk\AppData\Local\Programs\Python\Python312\Lib\asyncio\tasks.py", line 454, in wait
    return await _wait(fs, timeout, return_when, loop)
           ^^^^^^^^^^^^^^^^^^^^^^^^^^^^^^^^^^^^^^^^^^^
  File "C:\Users\amitk\AppData\Local\Programs\Python\Python312\Lib\asyncio\tasks.py", line 540, in _wait
    await waiter
asyncio.exceptions.CancelledError

The above exception was the direct cause of the following exception:

Traceback (most recent call last):
  File "C:\Users\amitk\AppData\Local\Programs\Python\Python312\Lib\site-packages\discord\ext\commands\core.py", line 235, in wrapped
    ret = await coro(*args, **kwargs)
          ^^^^^^^^^^^^^^^^^^^^^^^^^^^
  File "C:\Users\amitk\Documents\Music Bot\commands\music.py", line 64, in play
  File "C:\Users\amitk\AppData\Local\Programs\Python\Python312\Lib\site-packages\discord\abc.py", line 1992, in connect
    await voice.connect(timeout=timeout, reconnect=reconnect, self_deaf=self_deaf, self_mute=self_mute)
  File "C:\Users\amitk\AppData\Local\Programs\Python\Python312\Lib\site-packages\discord\voice_client.py", line 306, in connect
    await self._connection.connect(
  File "C:\Users\amitk\AppData\Local\Programs\Python\Python312\Lib\site-packages\discord\voice_state.py", line 380, in connect
    await self._connector
  File "C:\Users\amitk\AppData\Local\Programs\Python\Python312\Lib\site-packages\discord\voice_state.py", line 384, in _wrap_connect
    await self._connect(*args)
  File "C:\Users\amitk\AppData\Local\Programs\Python\Python312\Lib\site-packages\discord\voice_state.py", line 429, in _connect
    await asyncio.wait_for(
  File "C:\Users\amitk\AppData\Local\Programs\Python\Python312\Lib\asyncio\tasks.py", line 509, in wait_for
    async with timeouts.timeout(timeout):
  File "C:\Users\amitk\AppData\Local\Programs\Python\Python312\Lib\asyncio\timeouts.py", line 111, in __aexit__
    raise TimeoutError from exc_val
TimeoutError

The above exception was the direct cause of the following exception:

Traceback (most recent call last):
  File "C:\Users\amitk\AppData\Local\Programs\Python\Python312\Lib\site-packages\discord\ext\commands\bot.py", line 1366, in invoke
    await ctx.command.invoke(ctx)
  File "C:\Users\amitk\AppData\Local\Programs\Python\Python312\Lib\site-packages\discord\ext\commands\core.py", line 1029, in invoke
    await injected(*ctx.args, **ctx.kwargs)  # type: ignore
    ^^^^^^^^^^^^^^^^^^^^^^^^^^^^^^^^^^^^^^^
  File "C:\Users\amitk\AppData\Local\Programs\Python\Python312\Lib\site-packages\discord\ext\commands\core.py", line 244, in wrapped
    raise CommandInvokeError(exc) from exc
discord.ext.commands.errors.CommandInvokeError: Command raised an exception: TimeoutError: 
2025-07-30 00:25:38,622 - ERROR - [play_command_error] Command raised an exception: TimeoutError:  | Additional info: {'guild_id': 1208701086458847282, 'user_id': 482482011571748864}
Traceback (most recent call last):
  File "C:\Users\amitk\AppData\Local\Programs\Python\Python312\Lib\asyncio\tasks.py", line 510, in wait_for
    return await fut
           ^^^^^^^^^
  File "C:\Users\amitk\AppData\Local\Programs\Python\Python312\Lib\site-packages\discord\voice_state.py", line 407, in _inner_connect
    await self._wait_for_state(ConnectionFlowState.got_both_voice_updates)
  File "C:\Users\amitk\AppData\Local\Programs\Python\Python312\Lib\site-packages\discord\voice_state.py", line 559, in _wait_for_state
    await sane_wait_for([self._state_event.wait()], timeout=timeout)
  File "C:\Users\amitk\AppData\Local\Programs\Python\Python312\Lib\site-packages\discord\utils.py", line 735, in sane_wait_for
    done, pending = await asyncio.wait(ensured, timeout=timeout, return_when=asyncio.ALL_COMPLETED)
                    ^^^^^^^^^^^^^^^^^^^^^^^^^^^^^^^^^^^^^^^^^^^^^^^^^^^^^^^^^^^^^^^^^^^^^^^^^^^^^^^
  File "C:\Users\amitk\AppData\Local\Programs\Python\Python312\Lib\asyncio\tasks.py", line 454, in wait
    return await _wait(fs, timeout, return_when, loop)
           ^^^^^^^^^^^^^^^^^^^^^^^^^^^^^^^^^^^^^^^^^^^
  File "C:\Users\amitk\AppData\Local\Programs\Python\Python312\Lib\asyncio\tasks.py", line 540, in _wait
    await waiter
asyncio.exceptions.CancelledError

The above exception was the direct cause of the following exception:

Traceback (most recent call last):
  File "C:\Users\amitk\AppData\Local\Programs\Python\Python312\Lib\site-packages\discord\ext\commands\core.py", line 235, in wrapped
    ret = await coro(*args, **kwargs)
          ^^^^^^^^^^^^^^^^^^^^^^^^^^^
  File "C:\Users\amitk\Documents\Music Bot\commands\music.py", line 64, in play
  File "C:\Users\amitk\AppData\Local\Programs\Python\Python312\Lib\site-packages\discord\abc.py", line 1992, in connect
    await voice.connect(timeout=timeout, reconnect=reconnect, self_deaf=self_deaf, self_mute=self_mute)
  File "C:\Users\amitk\AppData\Local\Programs\Python\Python312\Lib\site-packages\discord\voice_client.py", line 306, in connect
    await self._connection.connect(
  File "C:\Users\amitk\AppData\Local\Programs\Python\Python312\Lib\site-packages\discord\voice_state.py", line 380, in connect
    await self._connector
  File "C:\Users\amitk\AppData\Local\Programs\Python\Python312\Lib\site-packages\discord\voice_state.py", line 384, in _wrap_connect
    await self._connect(*args)
  File "C:\Users\amitk\AppData\Local\Programs\Python\Python312\Lib\site-packages\discord\voice_state.py", line 429, in _connect
    await asyncio.wait_for(
  File "C:\Users\amitk\AppData\Local\Programs\Python\Python312\Lib\asyncio\tasks.py", line 509, in wait_for
    async with timeouts.timeout(timeout):
  File "C:\Users\amitk\AppData\Local\Programs\Python\Python312\Lib\asyncio\timeouts.py", line 111, in __aexit__
    raise TimeoutError from exc_val
TimeoutError

The above exception was the direct cause of the following exception:

Traceback (most recent call last):
  File "C:\Users\amitk\AppData\Local\Programs\Python\Python312\Lib\site-packages\discord\ext\commands\bot.py", line 1366, in invoke
    await ctx.command.invoke(ctx)
  File "C:\Users\amitk\AppData\Local\Programs\Python\Python312\Lib\site-packages\discord\ext\commands\core.py", line 1029, in invoke
    await injected(*ctx.args, **ctx.kwargs)  # type: ignore
    ^^^^^^^^^^^^^^^^^^^^^^^^^^^^^^^^^^^^^^^
  File "C:\Users\amitk\AppData\Local\Programs\Python\Python312\Lib\site-packages\discord\ext\commands\core.py", line 244, in wrapped
    raise CommandInvokeError(exc) from exc
discord.ext.commands.errors.CommandInvokeError: Command raised an exception: TimeoutError: 
2025-07-30 00:25:39,740 - ERROR - [command_error] Command raised an exception: TimeoutError:  | Additional info: {'guild_id': 1208701086458847282}
NoneType: None
2025-07-30 00:25:40,249 - ERROR - [command_error] Command raised an exception: TimeoutError:  | Additional info: {'guild_id': 1208701086458847282}
NoneType: None
2025-07-30 00:29:09,933 - INFO - Dashboard background updates stopped
2025-07-30 00:29:10,316 - INFO - Starting enhanced dashboard on http://127.0.0.1:5000
2025-07-30 00:30:47,306 - INFO - Starting Music Bot...
2025-07-30 00:30:48,351 - INFO - Starting bot setup...
2025-07-30 00:30:48,358 - INFO - All command modules loaded successfully
2025-07-30 00:30:48,359 - INFO - Bot setup completed successfully
2025-07-30 00:30:51,455 - INFO - Bot is ready! Logged in as Neha (1397919621473894470)
2025-07-30 00:30:51,455 - INFO - Connected to 4 guilds
2025-07-30 00:30:51,455 - INFO - Serving 295 users
2025-07-30 00:31:02,476 - INFO - Starting enhanced dashboard on http://127.0.0.1:5000
2025-07-30 00:31:02,817 - INFO - Starting enhanced dashboard on http://127.0.0.1:5000
2025-07-30 00:38:46,434 - INFO - Dashboard background updates stopped
2025-07-30 00:38:46,824 - INFO - Starting enhanced dashboard on http://127.0.0.1:5000
2025-07-30 01:52:34,940 - INFO - Dashboard background updates stopped
2025-07-30 01:52:35,339 - INFO - Starting enhanced dashboard on http://127.0.0.1:5000
2025-07-30 01:54:22,899 - INFO - Dashboard background updates stopped
2025-07-30 01:54:23,306 - INFO - Starting enhanced dashboard on http://127.0.0.1:5000
2025-07-30 02:07:41,261 - INFO - Dashboard background updates stopped
2025-07-30 17:24:34,369 - INFO - Starting Music Bot...
2025-07-30 17:24:35,390 - INFO - Starting bot setup...
2025-07-30 17:24:35,399 - INFO - All command modules loaded successfully
2025-07-30 17:24:35,399 - INFO - Bot setup completed successfully
2025-07-30 17:24:38,375 - INFO - Bot is ready! Logged in as Neha (1397919621473894470)
2025-07-30 17:24:38,375 - INFO - Connected to 4 guilds
2025-07-30 17:24:38,375 - INFO - Serving 295 users
2025-07-30 17:24:49,826 - INFO - Command used | Guild: funny server (1053223116085673985) | User: itsvirus07#0 (482482011571748864) | Command: play Args: aje na ja
2025-07-30 17:25:00,571 - INFO - Audio event: song_resolved | Guild: 0 | Song: Aje Na Jaa - Simran Choudhary | Official Video (attempt 1)
2025-07-30 17:25:00,596 - INFO - Recorded song play: Aje Na Jaa - Simran Choudhary | Official Video in guild 1053223116085673985 (funny server)
2025-07-30 17:25:01,635 - INFO - Audio event: song_started | Guild: 1053223116085673985 | Song: Aje Na Jaa - Simran Choudhary | Official Video
2025-07-30 17:25:04,116 - INFO - Audio event: songs_added | Guild: 1053223116085673985 | Song: 1 songs
2025-07-30 17:27:45,174 - INFO - Audio event: queue_finished | Guild: 1053223116085673985
2025-07-30 17:31:54,342 - INFO - Starting Music Bot...
2025-07-30 17:31:55,342 - INFO - Starting bot setup...
2025-07-30 17:31:55,346 - INFO - All command modules loaded successfully
2025-07-30 17:31:55,346 - INFO - Bot setup completed successfully
2025-07-30 17:31:58,274 - INFO - Bot is ready! Logged in as Neha (1397919621473894470)
2025-07-30 17:31:58,274 - INFO - Connected to 4 guilds
2025-07-30 17:31:58,274 - INFO - Serving 295 users
2025-07-30 23:57:49,340 - INFO - Command used | Guild: BhaluGang (1208701086458847282) | User: itsvirus07#0 (482482011571748864) | Command: play Args: https://www.youtube.com/watch?v=jUDP6LmgcCE&list=RDG4NAKKy5k0g&index=26
2025-07-30 23:59:03,642 - INFO - Audio event: song_resolved | Guild: 0 | Song: Mann Ki Lagan | Rahat Fateh Ali Khan | John Abraham | Paap (attempt 1)
2025-07-30 23:59:03,649 - INFO - Recorded song play: Mann Ki Lagan | Rahat Fateh Ali Khan | John Abraham | Paap in guild 1208701086458847282 (BhaluGang)
2025-07-30 23:59:04,779 - INFO - Audio event: song_started | Guild: 1208701086458847282 | Song: Mann Ki Lagan | Rahat Fateh Ali Khan | John Abraham | Paap
2025-07-30 23:59:09,614 - INFO - Audio event: playlist_completed | Guild: 1208701086458847282 | Song: 20 songs
2025-07-31 00:04:18,377 - INFO - Audio event: song_resolved | Guild: 0 | Song: Pankaj Udhas - Chandi Jaisa Rang (attempt 1)
2025-07-31 00:04:18,383 - INFO - Recorded song play: Pankaj Udhas - Chandi Jaisa Rang in guild 1208701086458847282 (BhaluGang)
2025-07-31 00:04:20,759 - INFO - Audio event: song_started | Guild: 1208701086458847282 | Song: Pankaj Udhas - Chandi Jaisa Rang
2025-07-31 00:08:58,984 - INFO - Audio event: song_resolved | Guild: 0 | Song: Saiyyan - Kailash Kher| Paresh Kamath| Naresh Kamath | Jhoomo Re (attempt 1)
2025-07-31 00:08:58,989 - INFO - Recorded song play: Saiyyan - Kailash Kher| Paresh Kamath| Naresh Kamath | Jhoomo Re in guild 1208701086458847282 (BhaluGang)
2025-07-31 00:09:01,141 - INFO - Audio event: song_started | Guild: 1208701086458847282 | Song: Saiyyan - Kailash Kher| Paresh Kamath| Naresh Kamath | Jhoomo Re
2025-07-31 00:14:11,640 - INFO - Audio event: song_resolved | Guild: 0 | Song: Main Jahaan Rahoon - Lyrical Video | Akshay Kumar | Katrina | Namastey London | Rahat Fateh Ali Khan (attempt 1)
2025-07-31 00:14:11,645 - INFO - Recorded song play: Main Jahaan Rahoon - Lyrical Video | Akshay Kumar | Katrina | Namastey London | Rahat Fateh Ali Khan in guild 1208701086458847282 (BhaluGang)
2025-07-31 00:14:14,026 - INFO - Audio event: song_started | Guild: 1208701086458847282 | Song: Main Jahaan Rahoon - Lyrical Video | Akshay Kumar | Katrina | Namastey London | Rahat Fateh Ali Khan
2025-07-31 00:20:36,279 - INFO - Audio event: song_resolved | Guild: 0 | Song: Maula Mere Maula | Anwar (2007) | Siddharth Koirala | Nauheed Cyrusi| Bollywood Romantic Song (attempt 1)
2025-07-31 00:20:36,283 - INFO - Recorded song play: Maula Mere Maula | Anwar (2007) | Siddharth Koirala | Nauheed Cyrusi| Bollywood Romantic Song in guild 1208701086458847282 (BhaluGang)
2025-07-31 00:20:38,415 - INFO - Audio event: song_started | Guild: 1208701086458847282 | Song: Maula Mere Maula | Anwar (2007) | Siddharth Koirala | Nauheed Cyrusi| Bollywood Romantic Song
2025-07-31 00:25:27,595 - INFO - Audio event: song_resolved | Guild: 0 | Song: A.R. Rahman - Tere Bina | Lyrical Song | Aishwarya Rai | Abhishek Bachchan | Guru | Gulzar (attempt 1)
2025-07-31 00:25:27,600 - INFO - Recorded song play: A.R. Rahman - Tere Bina | Lyrical Song | Aishwarya Rai | Abhishek Bachchan | Guru | Gulzar in guild 1208701086458847282 (BhaluGang)
2025-07-31 00:25:29,435 - INFO - Audio event: song_started | Guild: 1208701086458847282 | Song: A.R. Rahman - Tere Bina | Lyrical Song | Aishwarya Rai | Abhishek Bachchan | Guru | Gulzar
2025-07-31 00:30:39,602 - INFO - Audio event: song_resolved | Guild: 0 | Song: Lyrical:Tum Jo Aaye |Once Upon A Time In Mumbai| Ajay Devgn,Rahat Fateh Ali Khan,Tulsi Kumar, Pritam (attempt 1)
2025-07-31 00:30:39,606 - INFO - Recorded song play: Lyrical:Tum Jo Aaye |Once Upon A Time In Mumbai| Ajay Devgn,Rahat Fateh Ali Khan,Tulsi Kumar, Pritam in guild 1208701086458847282 (BhaluGang)
2025-07-31 00:30:41,769 - INFO - Audio event: song_started | Guild: 1208701086458847282 | Song: Lyrical:Tum Jo Aaye |Once Upon A Time In Mumbai| Ajay Devgn,Rahat Fateh Ali Khan,Tulsi Kumar, Pritam
2025-07-31 00:35:47,443 - INFO - Audio event: song_resolved | Guild: 0 | Song: Tu Jaane Na - Lyrical | Ajab Prem Ki Ghazab Kahani | Atif Aslam | Ranbir Kapoor, Katrina (attempt 1)
2025-07-31 00:35:47,448 - INFO - Recorded song play: Tu Jaane Na - Lyrical | Ajab Prem Ki Ghazab Kahani | Atif Aslam | Ranbir Kapoor, Katrina in guild 1208701086458847282 (BhaluGang)
2025-07-31 00:35:49,681 - INFO - Audio event: song_started | Guild: 1208701086458847282 | Song: Tu Jaane Na - Lyrical | Ajab Prem Ki Ghazab Kahani | Atif Aslam | Ranbir Kapoor, Katrina
2025-07-31 00:41:27,922 - INFO - Audio event: song_resolved | Guild: 0 | Song: Adnan Sami "Tera Chehra" Full Video Song HD (Sad Version) Feat. Rani Mukherjee (attempt 1)
2025-07-31 00:41:27,926 - INFO - Recorded song play: Adnan Sami "Tera Chehra" Full Video Song HD (Sad Version) Feat. Rani Mukherjee in guild 1208701086458847282 (BhaluGang)
2025-07-31 00:41:30,036 - INFO - Audio event: song_started | Guild: 1208701086458847282 | Song: Adnan Sami "Tera Chehra" Full Video Song HD (Sad Version) Feat. Rani Mukherjee
2025-07-31 00:46:50,162 - INFO - Audio event: song_resolved | Guild: 0 | Song: Ishq Sufiyana Lyrical | The Dirty Picture | Emraan Hashmi,Vidya Balan | Vishal - Shekhar (attempt 1)
2025-07-31 00:46:50,167 - INFO - Recorded song play: Ishq Sufiyana Lyrical | The Dirty Picture | Emraan Hashmi,Vidya Balan | Vishal - Shekhar in guild 1208701086458847282 (BhaluGang)
2025-07-31 00:46:52,151 - INFO - Audio event: song_started | Guild: 1208701086458847282 | Song: Ishq Sufiyana Lyrical | The Dirty Picture | Emraan Hashmi,Vidya Balan | Vishal - Shekhar
2025-07-31 00:52:37,770 - INFO - Audio event: song_resolved | Guild: 0 | Song: Lyrical: Saude Bazi | Aakrosh | Ajay Devgn, Bipasha Basu | Pritam | Anupam Amod | Irshad Kamil (attempt 1)
2025-07-31 00:52:37,775 - INFO - Recorded song play: Lyrical: Saude Bazi | Aakrosh | Ajay Devgn, Bipasha Basu | Pritam | Anupam Amod | Irshad Kamil in guild 1208701086458847282 (BhaluGang)
2025-07-31 00:52:39,790 - INFO - Audio event: song_started | Guild: 1208701086458847282 | Song: Lyrical: Saude Bazi | Aakrosh | Ajay Devgn, Bipasha Basu | Pritam | Anupam Amod | Irshad Kamil
2025-07-31 00:58:56,430 - INFO - Audio event: song_resolved | Guild: 0 | Song: Bin Tere - Lyrical Song | I Hate Luv Storys | Sonam Kapoor, Imran Khan | Vishal & Shekhar (attempt 1)
2025-07-31 00:58:56,437 - INFO - Recorded song play: Bin Tere - Lyrical Song | I Hate Luv Storys | Sonam Kapoor, Imran Khan | Vishal & Shekhar in guild 1208701086458847282 (BhaluGang)
2025-07-31 00:58:58,204 - INFO - Audio event: song_started | Guild: 1208701086458847282 | Song: Bin Tere - Lyrical Song | I Hate Luv Storys | Sonam Kapoor, Imran Khan | Vishal & Shekhar
2025-07-31 01:04:32,106 - INFO - Audio event: song_resolved | Guild: 0 | Song: Tum Se Hi Lyrcial | Jab We Met | Kareena Kapoor, Shahid Kapoor | Mohit Chauhan | Pritam (attempt 1)
2025-07-31 01:04:32,113 - INFO - Recorded song play: Tum Se Hi Lyrcial | Jab We Met | Kareena Kapoor, Shahid Kapoor | Mohit Chauhan | Pritam in guild 1208701086458847282 (BhaluGang)
2025-07-31 01:04:35,411 - INFO - Audio event: song_started | Guild: 1208701086458847282 | Song: Tum Se Hi Lyrcial | Jab We Met | Kareena Kapoor, Shahid Kapoor | Mohit Chauhan | Pritam
2025-07-31 01:10:15,087 - INFO - Audio event: song_resolved | Guild: 0 | Song: Rockstar: Tum Ho (Lyrical Video) Song | Ranbir Kapoor | Nargis | A R Rahman, Mohit Chauhan, Kavita (attempt 1)
2025-07-31 01:10:15,094 - INFO - Recorded song play: Rockstar: Tum Ho (Lyrical Video) Song | Ranbir Kapoor | Nargis | A R Rahman, Mohit Chauhan, Kavita in guild 1208701086458847282 (BhaluGang)
2025-07-31 01:10:16,886 - INFO - Audio event: song_started | Guild: 1208701086458847282 | Song: Rockstar: Tum Ho (Lyrical Video) Song | Ranbir Kapoor | Nargis | A R Rahman, Mohit Chauhan, Kavita
2025-07-31 01:15:26,913 - INFO - Bot stopped by user
2025-07-31 01:15:30,889 - INFO - Starting Music Bot...
2025-07-31 01:15:31,832 - INFO - Starting bot setup...
2025-07-31 01:15:31,845 - ERROR - [setup_hook] Extension 'commands.admin' raised an error: CommandRegistrationError: The command clearqueue is already an existing command or alias.
Traceback (most recent call last):
  File "C:\Users\amitk\AppData\Local\Programs\Python\Python312\Lib\site-packages\discord\ext\commands\bot.py", line 963, in _load_from_module_spec
    await setup(self)
  File "C:\Users\amitk\Documents\Music Bot\commands\admin.py", line 215, in setup
    await bot.add_cog(AdminCog(bot))
  File "C:\Users\amitk\AppData\Local\Programs\Python\Python312\Lib\site-packages\discord\ext\commands\bot.py", line 799, in add_cog
    cog = await cog._inject(self, override=override, guild=guild, guilds=guilds)
          ^^^^^^^^^^^^^^^^^^^^^^^^^^^^^^^^^^^^^^^^^^^^^^^^^^^^^^^^^^^^^^^^^^^^^^
  File "C:\Users\amitk\AppData\Local\Programs\Python\Python312\Lib\site-packages\discord\ext\commands\cog.py", line 725, in _inject
    raise e
  File "C:\Users\amitk\AppData\Local\Programs\Python\Python312\Lib\site-packages\discord\ext\commands\cog.py", line 716, in _inject
    bot.add_command(command)
  File "C:\Users\amitk\AppData\Local\Programs\Python\Python312\Lib\site-packages\discord\ext\commands\bot.py", line 253, in add_command
    super().add_command(command)
  File "C:\Users\amitk\AppData\Local\Programs\Python\Python312\Lib\site-packages\discord\ext\commands\core.py", line 1356, in add_command
    raise CommandRegistrationError(command.name)
discord.ext.commands.errors.CommandRegistrationError: The command clearqueue is already an existing command or alias.

The above exception was the direct cause of the following exception:

Traceback (most recent call last):
  File "C:\Users\amitk\Documents\Music Bot\bot.py", line 38, in setup_hook
    await self.load_extension('commands.admin')
  File "C:\Users\amitk\AppData\Local\Programs\Python\Python312\Lib\site-packages\discord\ext\commands\bot.py", line 1029, in load_extension
    await self._load_from_module_spec(spec, name)
  File "C:\Users\amitk\AppData\Local\Programs\Python\Python312\Lib\site-packages\discord\ext\commands\bot.py", line 968, in _load_from_module_spec
    raise errors.ExtensionFailed(key, e) from e
discord.ext.commands.errors.ExtensionFailed: Extension 'commands.admin' raised an error: CommandRegistrationError: The command clearqueue is already an existing command or alias.
2025-07-31 01:15:31,847 - ERROR - [bot_startup] Extension 'commands.admin' raised an error: CommandRegistrationError: The command clearqueue is already an existing command or alias.
Traceback (most recent call last):
  File "C:\Users\amitk\AppData\Local\Programs\Python\Python312\Lib\site-packages\discord\ext\commands\bot.py", line 963, in _load_from_module_spec
    await setup(self)
  File "C:\Users\amitk\Documents\Music Bot\commands\admin.py", line 215, in setup
    await bot.add_cog(AdminCog(bot))
  File "C:\Users\amitk\AppData\Local\Programs\Python\Python312\Lib\site-packages\discord\ext\commands\bot.py", line 799, in add_cog
    cog = await cog._inject(self, override=override, guild=guild, guilds=guilds)
          ^^^^^^^^^^^^^^^^^^^^^^^^^^^^^^^^^^^^^^^^^^^^^^^^^^^^^^^^^^^^^^^^^^^^^^
  File "C:\Users\amitk\AppData\Local\Programs\Python\Python312\Lib\site-packages\discord\ext\commands\cog.py", line 725, in _inject
    raise e
  File "C:\Users\amitk\AppData\Local\Programs\Python\Python312\Lib\site-packages\discord\ext\commands\cog.py", line 716, in _inject
    bot.add_command(command)
  File "C:\Users\amitk\AppData\Local\Programs\Python\Python312\Lib\site-packages\discord\ext\commands\bot.py", line 253, in add_command
    super().add_command(command)
  File "C:\Users\amitk\AppData\Local\Programs\Python\Python312\Lib\site-packages\discord\ext\commands\core.py", line 1356, in add_command
    raise CommandRegistrationError(command.name)
discord.ext.commands.errors.CommandRegistrationError: The command clearqueue is already an existing command or alias.

The above exception was the direct cause of the following exception:

Traceback (most recent call last):
  File "C:\Users\amitk\Documents\Music Bot\bot.py", line 271, in main
    await bot.start(config.discord_token)
  File "C:\Users\amitk\AppData\Local\Programs\Python\Python312\Lib\site-packages\discord\client.py", line 823, in start
    await self.login(token)
  File "C:\Users\amitk\AppData\Local\Programs\Python\Python312\Lib\site-packages\discord\client.py", line 666, in login
    await self.setup_hook()
  File "C:\Users\amitk\Documents\Music Bot\bot.py", line 38, in setup_hook
    await self.load_extension('commands.admin')
  File "C:\Users\amitk\AppData\Local\Programs\Python\Python312\Lib\site-packages\discord\ext\commands\bot.py", line 1029, in load_extension
    await self._load_from_module_spec(spec, name)
  File "C:\Users\amitk\AppData\Local\Programs\Python\Python312\Lib\site-packages\discord\ext\commands\bot.py", line 968, in _load_from_module_spec
    raise errors.ExtensionFailed(key, e) from e
discord.ext.commands.errors.ExtensionFailed: Extension 'commands.admin' raised an error: CommandRegistrationError: The command clearqueue is already an existing command or alias.
2025-07-31 01:15:31,848 - ERROR - [main_execution] Extension 'commands.admin' raised an error: CommandRegistrationError: The command clearqueue is already an existing command or alias.
Traceback (most recent call last):
  File "C:\Users\amitk\AppData\Local\Programs\Python\Python312\Lib\site-packages\discord\ext\commands\bot.py", line 963, in _load_from_module_spec
    await setup(self)
  File "C:\Users\amitk\Documents\Music Bot\commands\admin.py", line 215, in setup
    await bot.add_cog(AdminCog(bot))
  File "C:\Users\amitk\AppData\Local\Programs\Python\Python312\Lib\site-packages\discord\ext\commands\bot.py", line 799, in add_cog
    cog = await cog._inject(self, override=override, guild=guild, guilds=guilds)
          ^^^^^^^^^^^^^^^^^^^^^^^^^^^^^^^^^^^^^^^^^^^^^^^^^^^^^^^^^^^^^^^^^^^^^^
  File "C:\Users\amitk\AppData\Local\Programs\Python\Python312\Lib\site-packages\discord\ext\commands\cog.py", line 725, in _inject
    raise e
  File "C:\Users\amitk\AppData\Local\Programs\Python\Python312\Lib\site-packages\discord\ext\commands\cog.py", line 716, in _inject
    bot.add_command(command)
  File "C:\Users\amitk\AppData\Local\Programs\Python\Python312\Lib\site-packages\discord\ext\commands\bot.py", line 253, in add_command
    super().add_command(command)
  File "C:\Users\amitk\AppData\Local\Programs\Python\Python312\Lib\site-packages\discord\ext\commands\core.py", line 1356, in add_command
    raise CommandRegistrationError(command.name)
discord.ext.commands.errors.CommandRegistrationError: The command clearqueue is already an existing command or alias.

The above exception was the direct cause of the following exception:

Traceback (most recent call last):
  File "C:\Users\amitk\Documents\Music Bot\bot.py", line 280, in <module>
    asyncio.run(main())
  File "C:\Users\amitk\AppData\Local\Programs\Python\Python312\Lib\asyncio\runners.py", line 194, in run
    return runner.run(main)
           ^^^^^^^^^^^^^^^^
  File "C:\Users\amitk\AppData\Local\Programs\Python\Python312\Lib\asyncio\runners.py", line 118, in run
    return self._loop.run_until_complete(task)
           ^^^^^^^^^^^^^^^^^^^^^^^^^^^^^^^^^^^
  File "C:\Users\amitk\AppData\Local\Programs\Python\Python312\Lib\asyncio\base_events.py", line 664, in run_until_complete
    return future.result()
           ^^^^^^^^^^^^^^^
  File "C:\Users\amitk\Documents\Music Bot\bot.py", line 271, in main
    await bot.start(config.discord_token)
  File "C:\Users\amitk\AppData\Local\Programs\Python\Python312\Lib\site-packages\discord\client.py", line 823, in start
    await self.login(token)
  File "C:\Users\amitk\AppData\Local\Programs\Python\Python312\Lib\site-packages\discord\client.py", line 666, in login
    await self.setup_hook()
  File "C:\Users\amitk\Documents\Music Bot\bot.py", line 38, in setup_hook
    await self.load_extension('commands.admin')
  File "C:\Users\amitk\AppData\Local\Programs\Python\Python312\Lib\site-packages\discord\ext\commands\bot.py", line 1029, in load_extension
    await self._load_from_module_spec(spec, name)
  File "C:\Users\amitk\AppData\Local\Programs\Python\Python312\Lib\site-packages\discord\ext\commands\bot.py", line 968, in _load_from_module_spec
    raise errors.ExtensionFailed(key, e) from e
discord.ext.commands.errors.ExtensionFailed: Extension 'commands.admin' raised an error: CommandRegistrationError: The command clearqueue is already an existing command or alias.
2025-07-31 01:16:32,999 - INFO - Starting Music Bot...
2025-07-31 01:16:33,941 - INFO - Starting bot setup...
2025-07-31 01:16:33,952 - INFO - All command modules loaded successfully
2025-07-31 01:16:33,952 - INFO - Bot setup completed successfully
2025-07-31 01:16:37,400 - INFO - Bot is ready! Logged in as Neha (1397919621473894470)
2025-07-31 01:16:37,400 - INFO - Connected to 4 guilds
2025-07-31 01:16:37,400 - INFO - Serving 296 users
2025-07-31 01:19:09,159 - INFO - Bot stopped by user
2025-07-31 01:19:12,444 - INFO - Starting Music Bot...
2025-07-31 01:19:13,422 - INFO - Starting bot setup...
2025-07-31 01:19:13,431 - INFO - All command modules loaded successfully
2025-07-31 01:19:13,431 - INFO - Bot setup completed successfully
2025-07-31 01:19:16,400 - INFO - Bot is ready! Logged in as Neha (1397919621473894470)
2025-07-31 01:19:16,400 - INFO - Connected to 4 guilds
2025-07-31 01:19:16,400 - INFO - Serving 296 users
2025-07-31 01:19:48,231 - INFO - Bot stopped by user
2025-07-31 01:19:52,034 - INFO - Starting Music Bot...
2025-07-31 01:19:53,203 - INFO - Starting bot setup...
2025-07-31 01:19:53,209 - INFO - All command modules loaded successfully
2025-07-31 01:19:53,209 - INFO - Bot setup completed successfully
2025-07-31 01:19:56,194 - INFO - Bot is ready! Logged in as Neha (1397919621473894470)
2025-07-31 01:19:56,194 - INFO - Connected to 4 guilds
2025-07-31 01:19:56,194 - INFO - Serving 296 users
2025-07-31 01:24:27,349 - INFO - Command used | Guild: BhaluGang (1208701086458847282) | User: bigbeesnase#0 (494299073487175690) | Command: play Args: sahiba
2025-07-31 01:24:37,323 - INFO - Audio event: song_resolved | Guild: 0 | Song: Sahiba (Official Music Video) : Aditya Rikhari, Ankita Chhetri | T-Series (attempt 1)
2025-07-31 01:24:37,331 - INFO - Recorded song play: Sahiba (Official Music Video) : Aditya Rikhari, Ankita Chhetri | T-Series in guild 1208701086458847282 (BhaluGang)
2025-07-31 01:24:38,350 - INFO - Audio event: song_started | Guild: 1208701086458847282 | Song: Sahiba (Official Music Video) : Aditya Rikhari, Ankita Chhetri | T-Series
2025-07-31 01:24:40,790 - INFO - Audio event: songs_added | Guild: 1208701086458847282 | Song: 1 songs
2025-07-31 01:24:45,226 - INFO - Command used | Guild: BhaluGang (1208701086458847282) | User: bigbeesnase#0 (494299073487175690) | Command: play Args: pal pal afusic
2025-07-31 01:24:53,094 - INFO - Audio event: songs_added | Guild: 1208701086458847282 | Song: 1 songs
